Workbook

Sheet Лист1
A1: Дата | B1: Территория | C1: Товарооборот, шт | D1: Товарооборот, руб | E1: Количество складов | F1: Количество заказов | G1: Количество клиентов | H1: Товарооборот на склад | I1: Неделя (по календарю) | J1: № п/п | K1: Неделя (по отчету)
A2: 43982 | B2: Самара | C2: 7944 | D2: 623971.5 | E2: =SUMIFS(Лист2!$C:$C,Лист2!$A:$A,$A2,Лист2!$B:$B,$B2) -> 15 | F2: =SUMIFS(Лист2!$D:$D,Лист2!$A:$A,$A2,Лист2!$B:$B,$B2) -> 441 | G2: =SUMIFS(Лист2!$E:$E,Лист2!$A:$A,$A2,Лист2!$B:$B,$B2) -> 368 | H2: =IFERROR($D2/$E2,0) -> 41598.1 | I2: =WEEKNUM($A2,21) -> 22 | J2: 1 | K2: Неделя 5 (25.05-31.05)
A3: 43981 | B3: Самара | C3: 10029 | D3: 787101 | E3: =SUMIFS(Лист2!$C:$C,Лист2!$A:$A,$A3,Лист2!$B:$B,$B3) -> 15 | F3: =SUMIFS(Лист2!$D:$D,Лист2!$A:$A,$A3,Лист2!$B:$B,$B3) -> 490 | G3: =SUMIFS(Лист2!$E:$E,Лист2!$A:$A,$A3,Лист2!$B:$B,$B3) -> 409 | H3: =IFERROR($D3/$E3,0) -> 52473.4 | I3: =WEEKNUM($A3,21) -> 22 | J3: 2 | K3: Неделя 5 (25.05-31.05)
A4: 43979 | B4: Самара | C4: 8536.5 | D4: 643944 | E4: =SUMIFS(Лист2!$C:$C,Лист2!$A:$A,$A4,Лист2!$B:$B,$B4) -> 15 | F4: =SUMIFS(Лист2!$D:$D,Лист2!$A:$A,$A4,Лист2!$B:$B,$B4) -> 464 | G4: =SUMIFS(Лист2!$E:$E,Лист2!$A:$A,$A4,Лист2!$B:$B,$B4) -> 390 | H4: =IFERROR($D4/$E4,0) -> 42929.6 | I4: =WEEKNUM($A4,21) -> 22 | J4: 3 | K4: Неделя 5 (25.05-31.05)
A5: 43967 | B5: Кемерово | C5: 38947.5 | D5: 3395892 | E5: =SUMIFS(Лист2!$C:$C,Лист2!$A:$A,$A5,Лист2!$B:$B,$B5) -> 21 | F5: =SUMIFS(Лист2!$D:$D,Лист2!$A:$A,$A5,Лист2!$B:$B,$B5) -> 2145 | G5: =SUMIFS(Лист2!$E:$E,Лист2!$A:$A,$A5,Лист2!$B:$B,$B5) -> 1947 | H5: =IFERROR($D5/$E5,0) -> 161709.14 | I5: =WEEKNUM($A5,21) -> 20 | J5: 4 | K5: Неделя 3 (11.05-17.05)
A6: 43970 | B6: Кемерово | C6: 31842 | D6: 2771116.5 | E6: =SUMIFS(Лист2!$C:$C,Лист2!$A:$A,$A6,Лист2!$B:$B,$B6) -> 21 | F6: =SUMIFS(Лист2!$D:$D,Лист2!$A:$A,$A6,Лист2!$B:$B,$B6) -> 1860 | G6: =SUMIFS(Лист2!$E:$E,Лист2!$A:$A,$A6,Лист2!$B:$B,$B6) -> 1704 | H6: =IFERROR($D6/$E6,0) -> 131957.93 | I6: =WEEKNUM($A6,21) -> 21 | J6: 5 | K6: Неделя 4 (18.05-24.05)
A7: 43968 | B7: Кемерово | C7: 32023.5 | D7: 2882458.5 | E7: =SUMIFS(Лист2!$C:$C,Лист2!$A:$A,$A7,Лист2!$B:$B,$B7) -> 21 | F7: =SUMIFS(Лист2!$D:$D,Лист2!$A:$A,$A7,Лист2!$B:$B,$B7) -> 1874 | G7: =SUMIFS(Лист2!$E:$E,Лист2!$A:$A,$A7,Лист2!$B:$B,$B7) -> 1705 | H7: =IFERROR($D7/$E7,0) -> 137259.93 | I7: =WEEKNUM($A7,21) -> 20 | J7: 6 | K7: Неделя 3 (11.05-17.05)
A8: 43960 | B8: Кемерово | C8: 31147.5 | D8: 2831019 | E8: =SUMIFS(Лист2!$C:$C,Лист2!$A:$A,$A8,Лист2!$B:$B,$B8) -> 21 | F8: =SUMIFS(Лист2!$D:$D,Лист2!$A:$A,$A8,Лист2!$B:$B,$B8) -> 1735 | G8: =SUMIFS(Лист2!$E:$E,Лист2!$A:$A,$A8,Лист2!$B:$B,$B8) -> 1568 | H8: =IFERROR($D8/$E8,0) -> 134810.43 | I8: =WEEKNUM($A8,21) -> 19 | J8: 7 | K8: Неделя 2 (04.05-10.05)
A9: 43955 | B9: Кемерово | C9: 25566 | D9: 2372310 | E9: =SUMIFS(Лист2!$C:$C,Лист2!$A:$A,$A9,Лист2!$B:$B,$B9) -> 20 | F9: =SUMIFS(Лист2!$D:$D,Лист2!$A:$A,$A9,Лист2!$B:$B,$B9) -> 1519 | G9: =SUMIFS(Лист2!$E:$E,Лист2!$A:$A,$A9,Лист2!$B:$B,$B9) -> 1372 | H9: =IFERROR($D9/$E9,0) -> 118615.5 | I9: =WEEKNUM($A9,21) -> 19 | J9: 8 | K9: Неделя 2 (04.05-10.05)
A10: 43950 | B10: Кемерово | C10: 29319 | D10: 2623480.5 | E10: =SUMIFS(Лист2!$C:$C,Лист2!$A:$A,$A10,Лист2!$B:$B,$B10) -> 18 | F10: =SUMIFS(Лист2!$D:$D,Лист2!$A:$A,$A10,Лист2!$B:$B,$B10) -> 1684 | G10: =SUMIFS(Лист2!$E:$E,Лист2!$A:$A,$A10,Лист2!$B:$B,$B10) -> 1528 | H10: =IFERROR($D10/$E10,0) -> 145748.92 | I10: =WEEKNUM($A10,21) -> 18 | J10: 9 | K10: Неделя 1 (29.04-03.05)
A11: 43953 | B11: Кемерово | C11: 29031 | D11: 2711247 | E11: =SUMIFS(Лист2!$C:$C,Лист2!$A:$A,$A11,Лист2!$B:$B,$B11) -> 18 | F11: =SUMIFS(Лист2!$D:$D,Лист2!$A:$A,$A11,Лист2!$B:$B,$B11) -> 1708 | G11: =SUMIFS(Лист2!$E:$E,Лист2!$A:$A,$A11,Лист2!$B:$B,$B11) -> 1534 | H11: =IFERROR($D11/$E11,0) -> 150624.83 | I11: =WEEKNUM($A11,21) -> 18 | J11: 10 | K11: Неделя 1 (29.04-03.05)
A12: 43977 | B12: Кемерово | C12: 33423 | D12: 2970330 | E12: =SUMIFS(Лист2!$C:$C,Лист2!$A:$A,$A12,Лист2!$B:$B,$B12) -> 20 | F12: =SUMIFS(Лист2!$D:$D,Лист2!$A:$A,$A12,Лист2!$B:$B,$B12) -> 2044 | G12: =SUMIFS(Лист2!$E:$E,Лист2!$A:$A,$A12,Лист2!$B:$B,$B12) -> 1863 | H12: =IFERROR($D12/$E12,0) -> 148516.5 | I12: =WEEKNUM($A12,21) -> 22 | J12: 11 | K12: Неделя 5 (25.05-31.05)
A13: 43952 | B13: Кемерово | C13: 32487 | D13: 3031254 | E13: =SUMIFS(Лист2!$C:$C,Лист2!$A:$A,$A13,Лист2!$B:$B,$B13) -> 18 | F13: =SUMIFS(Лист2!$D:$D,Лист2!$A:$A,$A13,Лист2!$B:$B,$B13) -> 1826 | G13: =SUMIFS(Лист2!$E:$E,Лист2!$A:$A,$A13,Лист2!$B:$B,$B13) -> 1633 | H13: =IFERROR($D13/$E13,0) -> 168403 | I13: =WEEKNUM($A13,21) -> 18 | J13: 12 | K13: Неделя 1 (29.04-03.05)
... A505: 43983 | B505: Новосибирск | C505: 14238 | D505: 1293219 | E505: =SUMIFS(Лист2!$C:$C,Лист2!$A:$A,$A505,Лист2!$B:$B,$B505) -> 18 | F505: =SUMIFS(Лист2!$D:$D,Лист2!$A:$A,$A505,Лист2!$B:$B,$B505) -> 923 | G505: =SUMIFS(Лист2!$E:$E,Лист2!$A:$A,$A505,Лист2!$B:$B,$B505) -> 824 | H505: =IFERROR($D505/$E505,0) -> 71845.5 | I505: =WEEKNUM($A505,21) -> 23 | J505: 504 | K505: Неделя 6 (01.06.20)

Sheet Лист2
A1: Дата | B1: Территория | C1: Количество складов | D1: Количество заказов | E1: Количество клиентов
A2: 43949 | B2: Волгоград | C2: 36 | D2: 4923 | E2: 4560
A3: 43949 | B3: Екатеринбург | C3: 31 | D3: 5465 | E3: 5096
A4: 43949 | B4: Казань | C4: 19 | D4: 1846 | E4: 1681
A5: 43949 | B5: Кемерово | C5: 18 | D5: 1539 | E5: 1404
A6: 43949 | B6: Краснодар | C6: 18 | D6: 1505 | E6: 1368
A7: 43949 | B7: Москва Восток | C7: 54 | D7: 12306 | E7: 11532
A8: 43949 | B8: Москва Запад | C8: 59 | D8: 12943 | E8: 12072
A9: 43949 | B9: Нижний Новгород | C9: 17 | D9: 1439 | E9: 1265
A10: 43949 | B10: Новосибирск | C10: 15 | D10: 636 | E10: 547
A11: 43949 | B11: Пермь | C11: 15 | D11: 780 | E11: 690
A12: 43949 | B12: Санкт-Петербург Север | C12: 125 | D12: 20914 | E12: 19479
A13: 43949 | B13: Санкт-Петербург Юг | C13: 128 | D13: 16450 | E13: 15320
... A505: 43983 | B505: Уфа | C505: 6 | D505: 237 | E505: 175

Sheet 1.1 Сводная таблица
A1: Сводная таблица по неделям и территориям
A3: 1) Товарооборот, руб
A4: Сумма по полю Товарооборот, руб | B4: Названия столбцов
A5: Названия строк | B5: Неделя 1 (29.04-03.05) | C5: Неделя 2 (04.05-10.05) | D5: Неделя 3 (11.05-17.05) | E5: Неделя 4 (18.05-24.05) | F5: Неделя 5 (25.05-31.05) | G5: Неделя 6 (01.06.20) | H5: Общий итог
A6: Волгоград | B6: 36934095 | C6: 43307156 | D6: 41300679 | E6: 44172813 | F6: 46485094 | G6: 5800290 | H6: 218000127
A7: Екатеринбург | B7: 42828758 | C7: 46366010 | D7: 47079842 | E7: 49575288 | F7: 50729186 | G7: 6829921.5 | H7: 2.43409e+08
A8: Казань | B8: 17828216 | C8: 20974521 | D8: 23603355 | E8: 26815804 | F8: 27495690 | G8: 3865251 | H8: 120582837
A9: Кемерово | B9: 16029680 | C9: 19479056 | D9: 19724733 | E9: 20915751 | F9: 22579281 | G9: 2945035.5 | H9: 1.0167354e+08
A10: Краснодар | B10: 13955985 | C10: 16391856 | D10: 16732521 | E10: 17647479 | F10: 18595773 | G10: 2538967.5 | H10: 85862582
A11: Москва Восток | B11: 130713645 | C11: 1.5164204e+08 | D11: 135813990 | E11: 149589546 | F11: 151451013 | G11: 18914194 | H11: 738124428
A12: Москва Запад | B12: 136791225 | C12: 159695760 | D12: 142825023 | E12: 1.5751236e+08 | F12: 1.5785721e+08 | G12: 19465372 | H12: 7.7414695e+08
A13: Нижний Новгород | B13: 13145966 | C13: 17149980 | D13: 19963154 | E13: 20713983 | F13: 21605704 | G13: 3013512 | H13: 95592298
A14: Новосибирск | B14: 5746024.5 | C14: 7253572.5 | D14: 7841920.5 | E14: 8990269.5 | F14: 9909624 | G14: 1293219 | H14: 41034630
A15: Пермь | B15: 6961020 | C15: 8778597 | D15: 9036316.5 | E15: 10598445 | F15: 11902053 | G15: 1526608.5 | H15: 48803040
A16: Ростов-на-Дону | B16: 2008809 | C16: 5892277.5 | D16: 7382458.5 | E16: 8638525.5 | F16: 9328845 | G16: 1565632.5 | H16: 34816548
A17: Самара | F17: 2706253.5 | G17: 636345 | H17: 3342598.5
A18: Санкт-Петербург Север | B18: 233059077 | C18: 2.727625e+08 | D18: 269949999 | E18: 2.7553943e+08 | F18: 2.9215505e+08 | G18: 37257840 | H18: 1.3807239e+09
A19: Санкт-Петербург Юг | B19: 176269533 | C19: 2.0812839e+08 | D19: 1.9956962e+08 | E19: 2.0460881e+08 | F19: 2.1926593e+08 | G19: 27770092 | H19: 1.0356124e+09
A20: Тольятти | B20: 4531000.5 | C20: 6093688.5 | D20: 6439392 | E20: 7373379 | F20: 7762362 | G20: 1007742 | H20: 33207564
A21: Томск | F21: 493893 | G21: 389013 | H21: 882906
A22: Тюмень | F22: 4861708.5 | G22: 802447.5 | H22: 5664156
A23: Уфа | F23: 468835.5 | G23: 410892 | H23: 879727.5
A24: Общий итог | B24: 836803032 | C24: 9.8391541e+08 | D24: 9.4726301e+08 | E24: 1.0026919e+09 | F24: 1.0556535e+09 | G24: 1.3603238e+08 | H24: 4.9623592e+09
A27: 2) Доля территории в общем товарообороте недели
A28: Сумма по полю Товарооборот, руб | B28: Названия столбцов
A29: Названия строк | B29: Неделя 1 (29.04-03.05) | C29: Неделя 2 (04.05-10.05) | D29: Неделя 3 (11.05-17.05) | E29: Неделя 4 (18.05-24.05) | F29: Неделя 5 (25.05-31.05) | G29: Неделя 6 (01.06.20) | H29: Общий итог
A30: Волгоград | B30: 0.044137143 | C30: 0.044015121 | D30: 0.043600013 | E30: 0.044054224 | F30: 0.044034424 | G30: 0.04263904 | H30: 0.043930743
A31: Екатеринбург | B31: 0.051181408 | C31: 0.047123979 | D31: 0.049700919 | E31: 0.049442195 | F31: 0.048054769 | G31: 0.050208058 | H31: 0.049051065
A32: Казань | B32: 0.021305152 | C32: 0.021317403 | D32: 0.024917425 | E32: 0.026743813 | F32: 0.026046131 | G32: 0.028414199 | H32: 0.024299498
A33: Кемерово | B33: 0.019155857 | C33: 0.01979749 | D33: 0.020822868 | E33: 0.020859599 | F33: 0.021388913 | G33: 0.021649519 | H33: 0.020488951
A34: Краснодар | B34: 0.016677742 | C34: 0.016659822 | D34: 0.017664071 | E34: 0.017600102 | F34: 0.017615413 | G34: 0.018664435 | H34: 0.017302774
A35: Москва Восток | B35: 0.15620599 | C35: 0.15412101 | D35: 0.14337517 | E35: 0.14918795 | F35: 0.14346659 | G35: 0.13904186 | H35: 0.14874466
A36: Москва Запад | B36: 0.16346884 | C36: 0.16230639 | D36: 0.15077652 | E36: 0.15708949 | F36: 0.14953506 | G36: 0.14309367 | H36: 0.15600381
A37: Нижний Новгород | B37: 0.015709749 | C37: 0.01743034 | D37: 0.021074563 | E37: 0.020658373 | F37: 0.020466663 | G37: 0.022152903 | H37: 0.019263478
A38: Новосибирск | B38: 0.0068666392 | C38: 0.0073721505 | D38: 0.0082785039 | E38: 0.0089661337 | F38: 0.0093871937 | G38: 0.0095067 | H38: 0.0082691777
A39: Пермь | B39: 0.0083185884 | C39: 0.0089221054 | D39: 0.0095393955 | E39: 0.010569992 | F39: 0.011274583 | G39: 0.011222391 | H39: 0.0098346447
A40: Ростов-на-Дону | B40: 0.0024005757 | C40: 0.0059886017 | D40: 0.0077934623 | E40: 0.008615334 | F40: 0.0088370331 | G40: 0.011509264 | H40: 0.0070161281
A41: Самара | B41: 0 | C41: 0 | D41: 0 | E41: 0 | F41: 0.0025635812 | G41: 0.0046778937 | H41: 0.0006735906
... A48: Общий итог | B48: 1 | C48: 1 | D48: 1 | E48: 1 | F48: 1 | G48: 1 | H48: 1
A51: 3) Товарооборот на склад, руб
...

Sheet 1.1.а Топ-3
B2: Топ-3 территорий за последнюю неделю
B4: Неделя анализа (по календарю): | C4: 22 | D4: =INDEX('1.2 Динамика'!$D$5:$D$10,MATCH($C$4,'1.2 Динамика'!$B$5:$B$10,0)) -> 43976 | E4: =INDEX('1.2 Динамика'!$E$5:$E$10,MATCH($C$4,'1.2 Динамика'!$B$5:$B$10,0)) -> 43982 | F4: ="дней в данных: "&INDEX('1.2 Динамика'!$F$5:$F$10,MATCH($C$4,'1.2 Динамика'!$B$5:$B$10,0)) -> дней в данных: 7
B5: Последняя полная неделя в данных — 22-я (25.05–31.05). 23-я неделя содержит данные только за 01.06, поэтому для вывода взята 22-я.
K6: Топ-3 по доле в общем товарообороте
B7: Территория | C7: Товарооборот, руб | D7: Доля в общем товарообороте | E7: Ранг по доле | F7: Товарооборот на склад, руб | G7: Ранг по ТО на склад | H7: Дней с продажами | I7: Складов (среднее) | K7: Место | L7: Территория | M7: Доля | N7: Товарооборот, руб
B8: Волгоград | C8: =SUMIFS(Лист1!$D:$D,Лист1!$B:$B,$B8,Лист1!$I:$I,$C$4) -> 46485094 | D8: =IFERROR(C8/$C$26,0) -> 0.044034424 | E8: =IF(C8=0,"–",RANK(D8,$D$8:$D$25)) -> 6 | F8: =SUMIFS(Лист1!$H:$H,Лист1!$B:$B,$B8,Лист1!$I:$I,$C$4) -> 1269533.7 | G8: =IF(F8=0,"–",RANK(F8,$F$8:$F$25)) -> 6 | H8: =COUNTIFS(Лист1!$B:$B,$B8,Лист1!$I:$I,$C$4) -> 7 | I8: =IFERROR(AVERAGEIFS(Лист1!$E:$E,Лист1!$B:$B,$B8,Лист1!$I:$I,$C$4),0) -> 36.571429 | K8: 1 | L8: =INDEX($B$8:$B$25,MATCH(1,$E$8:$E$25,0)) -> Санкт-Петербург Север | M8: =INDEX($D$8:$D$25,MATCH(1,$E$8:$E$25,0)) -> 0.27675279 | N8: =INDEX($C$8:$C$25,MATCH(1,$E$8:$E$25,0)) -> 2.9215505e+08
B9: Екатеринбург | C9: =SUMIFS(Лист1!$D:$D,Лист1!$B:$B,$B9,Лист1!$I:$I,$C$4) -> 50729186 | D9: =IFERROR(C9/$C$26,0) -> 0.048054769 | E9: =IF(C9=0,"–",RANK(D9,$D$8:$D$25)) -> 5 | F9: =SUMIFS(Лист1!$H:$H,Лист1!$B:$B,$B9,Лист1!$I:$I,$C$4) -> 1636425.3 | G9: =IF(F9=0,"–",RANK(F9,$F$8:$F$25)) -> 5 | H9: =COUNTIFS(Лист1!$B:$B,$B9,Лист1!$I:$I,$C$4) -> 7 | I9: =IFERROR(AVERAGEIFS(Лист1!$E:$E,Лист1!$B:$B,$B9,Лист1!$I:$I,$C$4),0) -> 31 | K9: 2 | L9: =INDEX($B$8:$B$25,MATCH(2,$E$8:$E$25,0)) -> Санкт-Петербург Юг | M9: =INDEX($D$8:$D$25,MATCH(2,$E$8:$E$25,0)) -> 0.20770634 | N9: =INDEX($C$8:$C$25,MATCH(2,$E$8:$E$25,0)) -> 2.1926593e+08
B10: Казань | C10: =SUMIFS(Лист1!$D:$D,Лист1!$B:$B,$B10,Лист1!$I:$I,$C$4) -> 27495690 | D10: =IFERROR(C10/$C$26,0) -> 0.026046131 | E10: =IF(C10=0,"–",RANK(D10,$D$8:$D$25)) -> 7 | F10: =SUMIFS(Лист1!$H:$H,Лист1!$B:$B,$B10,Лист1!$I:$I,$C$4) -> 1265812.7 | G10: =IF(F10=0,"–",RANK(F10,$F$8:$F$25)) -> 7 | H10: =COUNTIFS(Лист1!$B:$B,$B10,Лист1!$I:$I,$C$4) -> 7 | I10: =IFERROR(AVERAGEIFS(Лист1!$E:$E,Лист1!$B:$B,$B10,Лист1!$I:$I,$C$4),0) -> 21.714286 | K10: 3 | L10: =INDEX($B$8:$B$25,MATCH(3,$E$8:$E$25,0)) -> Москва Запад | M10: =INDEX($D$8:$D$25,MATCH(3,$E$8:$E$25,0)) -> 0.14953506 | N10: =INDEX($C$8:$C$25,MATCH(3,$E$8:$E$25,0)) -> 1.5785721e+08
B11: Кемерово | C11: =SUMIFS(Лист1!$D:$D,Лист1!$B:$B,$B11,Лист1!$I:$I,$C$4) -> 22579281 | D11: =IFERROR(C11/$C$26,0) -> 0.021388913 | E11: =IF(C11=0,"–",RANK(D11,$D$8:$D$25)) -> 8 | F11: =SUMIFS(Лист1!$H:$H,Лист1!$B:$B,$B11,Лист1!$I:$I,$C$4) -> 1120692.9 | G11: =IF(F11=0,"–",RANK(F11,$F$8:$F$25)) -> 8 | H11: =COUNTIFS(Лист1!$B:$B,$B11,Лист1!$I:$I,$C$4) -> 7 | I11: =IFERROR(AVERAGEIFS(Лист1!$E:$E,Лист1!$B:$B,$B11,Лист1!$I:$I,$C$4),0) -> 20.142857 | L11: Итого топ-3 | M11: =SUM(M8:M10) -> 0.63399419 | N11: =SUM(N8:N10) -> 6.6927819e+08
B12: Краснодар | C12: =SUMIFS(Лист1!$D:$D,Лист1!$B:$B,$B12,Лист1!$I:$I,$C$4) -> 18595773 | D12: =IFERROR(C12/$C$26,0) -> 0.017615413 | E12: =IF(C12=0,"–",RANK(D12,$D$8:$D$25)) -> 10 | F12: =SUMIFS(Лист1!$H:$H,Лист1!$B:$B,$B12,Лист1!$I:$I,$C$4) -> 923135.5 | G12: =IF(F12=0,"–",RANK(F12,$F$8:$F$25)) -> 10 | H12: =COUNTIFS(Лист1!$B:$B,$B12,Лист1!$I:$I,$C$4) -> 7 | I12: =IFERROR(AVERAGEIFS(Лист1!$E:$E,Лист1!$B:$B,$B12,Лист1!$I:$I,$C$4),0) -> 20.142857
B13: Москва Восток | C13: =SUMIFS(Лист1!$D:$D,Лист1!$B:$B,$B13,Лист1!$I:$I,$C$4) -> 151451013 | D13: =IFERROR(C13/$C$26,0) -> 0.14346659 | E13: =IF(C13=0,"–",RANK(D13,$D$8:$D$25)) -> 4 | F13: =SUMIFS(Лист1!$H:$H,Лист1!$B:$B,$B13,Лист1!$I:$I,$C$4) -> 2804648.4 | G13: =IF(F13=0,"–",RANK(F13,$F$8:$F$25)) -> 1 | H13: =COUNTIFS(Лист1!$B:$B,$B13,Лист1!$I:$I,$C$4) -> 7 | I13: =IFERROR(AVERAGEIFS(Лист1!$E:$E,Лист1!$B:$B,$B13,Лист1!$I:$I,$C$4),0) -> 54 | K13: Топ-3 по товарообороту на склад
B14: Москва Запад | C14: =SUMIFS(Лист1!$D:$D,Лист1!$B:$B,$B14,Лист1!$I:$I,$C$4) -> 1.5785721e+08 | D14: =IFERROR(C14/$C$26,0) -> 0.14953506 | E14: =IF(C14=0,"–",RANK(D14,$D$8:$D$25)) -> 3 | F14: =SUMIFS(Лист1!$H:$H,Лист1!$B:$B,$B14,Лист1!$I:$I,$C$4) -> 2669745 | G14: =IF(F14=0,"–",RANK(F14,$F$8:$F$25)) -> 2 | H14: =COUNTIFS(Лист1!$B:$B,$B14,Лист1!$I:$I,$C$4) -> 7 | I14: =IFERROR(AVERAGEIFS(Лист1!$E:$E,Лист1!$B:$B,$B14,Лист1!$I:$I,$C$4),0) -> 59.142857 | K14: Место | L14: Территория | M14: ТО на склад, руб | N14: Складов (среднее)
B15: Нижний Новгород | C15: =SUMIFS(Лист1!$D:$D,Лист1!$B:$B,$B15,Лист1!$I:$I,$C$4) -> 21605704 | D15: =IFERROR(C15/$C$26,0) -> 0.020466663 | E15: =IF(C15=0,"–",RANK(D15,$D$8:$D$25)) -> 9 | F15: =SUMIFS(Лист1!$H:$H,Лист1!$B:$B,$B15,Лист1!$I:$I,$C$4) -> 1080285.2 | G15: =IF(F15=0,"–",RANK(F15,$F$8:$F$25)) -> 9 | H15: =COUNTIFS(Лист1!$B:$B,$B15,Лист1!$I:$I,$C$4) -> 7 | I15: =IFERROR(AVERAGEIFS(Лист1!$E:$E,Лист1!$B:$B,$B15,Лист1!$I:$I,$C$4),0) -> 20 | K15: 1 | L15: =INDEX($B$8:$B$25,MATCH(1,$G$8:$G$25,0)) -> Москва Восток | M15: =INDEX($F$8:$F$25,MATCH(1,$G$8:$G$25,0)) -> 2804648.4 | N15: =INDEX($I$8:$I$25,MATCH(1,$G$8:$G$25,0)) -> 54
B16: Новосибирск | C16: =SUMIFS(Лист1!$D:$D,Лист1!$B:$B,$B16,Лист1!$I:$I,$C$4) -> 9909624 | D16: =IFERROR(C16/$C$26,0) -> 0.0093871937 | E16: =IF(C16=0,"–",RANK(D16,$D$8:$D$25)) -> 12 | F16: =SUMIFS(Лист1!$H:$H,Лист1!$B:$B,$B16,Лист1!$I:$I,$C$4) -> 550534.67 | G16: =IF(F16=0,"–",RANK(F16,$F$8:$F$25)) -> 15 | H16: =COUNTIFS(Лист1!$B:$B,$B16,Лист1!$I:$I,$C$4) -> 7 | I16: =IFERROR(AVERAGEIFS(Лист1!$E:$E,Лист1!$B:$B,$B16,Лист1!$I:$I,$C$4),0) -> 18 | K16: 2 | L16: =INDEX($B$8:$B$25,MATCH(2,$G$8:$G$25,0)) -> Москва Запад | M16: =INDEX($F$8:$F$25,MATCH(2,$G$8:$G$25,0)) -> 2669745 | N16: =INDEX($I$8:$I$25,MATCH(2,$G$8:$G$25,0)) -> 59.142857
B17: Пермь | C17: =SUMIFS(Лист1!$D:$D,Лист1!$B:$B,$B17,Лист1!$I:$I,$C$4) -> 11902053 | D17: =IFERROR(C17/$C$26,0) -> 0.011274583 | E17: =IF(C17=0,"–",RANK(D17,$D$8:$D$25)) -> 11 | F17: =SUMIFS(Лист1!$H:$H,Лист1!$B:$B,$B17,Лист1!$I:$I,$C$4) -> 700120.76 | G17: =IF(F17=0,"–",RANK(F17,$F$8:$F$25)) -> 12 | H17: =COUNTIFS(Лист1!$B:$B,$B17,Лист1!$I:$I,$C$4) -> 7 | I17: =IFERROR(AVERAGEIFS(Лист1!$E:$E,Лист1!$B:$B,$B17,Лист1!$I:$I,$C$4),0) -> 17 | K17: 3 | L17: =INDEX($B$8:$B$25,MATCH(3,$G$8:$G$25,0)) -> Санкт-Петербург Север | M17: =INDEX($F$8:$F$25,MATCH(3,$G$8:$G$25,0)) -> 2356089.1 | N17: =INDEX($I$8:$I$25,MATCH(3,$G$8:$G$25,0)) -> 124
B18: Ростов-на-Дону | C18: =SUMIFS(Лист1!$D:$D,Лист1!$B:$B,$B18,Лист1!$I:$I,$C$4) -> 9328845 | D18: =IFERROR(C18/$C$26,0) -> 0.0088370331 | E18: =IF(C18=0,"–",RANK(D18,$D$8:$D$25)) -> 13 | F18: =SUMIFS(Лист1!$H:$H,Лист1!$B:$B,$B18,Лист1!$I:$I,$C$4) -> 598028.64 | G18: =IF(F18=0,"–",RANK(F18,$F$8:$F$25)) -> 14 | H18: =COUNTIFS(Лист1!$B:$B,$B18,Лист1!$I:$I,$C$4) -> 7 | I18: =IFERROR(AVERAGEIFS(Лист1!$E:$E,Лист1!$B:$B,$B18,Лист1!$I:$I,$C$4),0) -> 15.571429 | L18: Среднее по сети | M18: =F26 -> 1779489.2
B19: Самара | C19: =SUMIFS(Лист1!$D:$D,Лист1!$B:$B,$B19,Лист1!$I:$I,$C$4) -> 2706253.5 | D19: =IFERROR(C19/$C$26,0) -> 0.0025635812 | E19: =IF(C19=0,"–",RANK(D19,$D$8:$D$25)) -> 16 | F19: =SUMIFS(Лист1!$H:$H,Лист1!$B:$B,$B19,Лист1!$I:$I,$C$4) -> 180416.9 | G19: =IF(F19=0,"–",RANK(F19,$F$8:$F$25)) -> 16 | H19: =COUNTIFS(Лист1!$B:$B,$B19,Лист1!$I:$I,$C$4) -> 4 | I19: =IFERROR(AVERAGEIFS(Лист1!$E:$E,Лист1!$B:$B,$B19,Лист1!$I:$I,$C$4),0) -> 15
B20: Санкт-Петербург Север | C20: =SUMIFS(Лист1!$D:$D,Лист1!$B:$B,$B20,Лист1!$I:$I,$C$4) -> 2.9215505e+08 | D20: =IFERROR(C20/$C$26,0) -> 0.27675279 | E20: =IF(C20=0,"–",RANK(D20,$D$8:$D$25)) -> 1 | F20: =SUMIFS(Лист1!$H:$H,Лист1!$B:$B,$B20,Лист1!$I:$I,$C$4) -> 2356089.1 | G20: =IF(F20=0,"–",RANK(F20,$F$8:$F$25)) -> 3 | H20: =COUNTIFS(Лист1!$B:$B,$B20,Лист1!$I:$I,$C$4) -> 7 | I20: =IFERROR(AVERAGEIFS(Лист1!$E:$E,Лист1!$B:$B,$B20,Лист1!$I:$I,$C$4),0) -> 124
B21: Санкт-Петербург Юг | C21: =SUMIFS(Лист1!$D:$D,Лист1!$B:$B,$B21,Лист1!$I:$I,$C$4) -> 2.1926593e+08 | D21: =IFERROR(C21/$C$26,0) -> 0.20770634 | E21: =IF(C21=0,"–",RANK(D21,$D$8:$D$25)) -> 2 | F21: =SUMIFS(Лист1!$H:$H,Лист1!$B:$B,$B21,Лист1!$I:$I,$C$4) -> 1699735.9 | G21: =IF(F21=0,"–",RANK(F21,$F$8:$F$25)) -> 4 | H21: =COUNTIFS(Лист1!$B:$B,$B21,Лист1!$I:$I,$C$4) -> 7 | I21: =IFERROR(AVERAGEIFS(Лист1!$E:$E,Лист1!$B:$B,$B21,Лист1!$I:$I,$C$4),0) -> 129
B22: Тольятти | C22: =SUMIFS(Лист1!$D:$D,Лист1!$B:$B,$B22,Лист1!$I:$I,$C$4) -> 7762362 | D22: =IFERROR(C22/$C$26,0) -> 0.0073531343 | E22: =IF(C22=0,"–",RANK(D22,$D$8:$D$25)) -> 14 | F22: =SUMIFS(Лист1!$H:$H,Лист1!$B:$B,$B22,Лист1!$I:$I,$C$4) -> 776236.2 | G22: =IF(F22=0,"–",RANK(F22,$F$8:$F$25)) -> 11 | H22: =COUNTIFS(Лист1!$B:$B,$B22,Лист1!$I:$I,$C$4) -> 7 | I22: =IFERROR(AVERAGEIFS(Лист1!$E:$E,Лист1!$B:$B,$B22,Лист1!$I:$I,$C$4),0) -> 10
B23: Томск | C23: =SUMIFS(Лист1!$D:$D,Лист1!$B:$B,$B23,Лист1!$I:$I,$C$4) -> 493893 | D23: =IFERROR(C23/$C$26,0) -> 0.00046785522 | E23: =IF(C23=0,"–",RANK(D23,$D$8:$D$25)) -> 17 | F23: =SUMIFS(Лист1!$H:$H,Лист1!$B:$B,$B23,Лист1!$I:$I,$C$4) -> 54877 | G23: =IF(F23=0,"–",RANK(F23,$F$8:$F$25)) -> 18 | H23: =COUNTIFS(Лист1!$B:$B,$B23,Лист1!$I:$I,$C$4) -> 1 | I23: =IFERROR(AVERAGEIFS(Лист1!$E:$E,Лист1!$B:$B,$B23,Лист1!$I:$I,$C$4),0) -> 9
B24: Тюмень | C24: =SUMIFS(Лист1!$D:$D,Лист1!$B:$B,$B24,Лист1!$I:$I,$C$4) -> 4861708.5 | D24: =IFERROR(C24/$C$26,0) -> 0.0046054017 | E24: =IF(C24=0,"–",RANK(D24,$D$8:$D$25)) -> 15 | F24: =SUMIFS(Лист1!$H:$H,Лист1!$B:$B,$B24,Лист1!$I:$I,$C$4) -> 694529.79 | G24: =IF(F24=0,"–",RANK(F24,$F$8:$F$25)) -> 13 | H24: =COUNTIFS(Лист1!$B:$B,$B24,Лист1!$I:$I,$C$4) -> 6 | I24: =IFERROR(AVERAGEIFS(Лист1!$E:$E,Лист1!$B:$B,$B24,Лист1!$I:$I,$C$4),0) -> 7
B25: Уфа | C25: =SUMIFS(Лист1!$D:$D,Лист1!$B:$B,$B25,Лист1!$I:$I,$C$4) -> 468835.5 | D25: =IFERROR(C25/$C$26,0) -> 0.00044411873 | E25: =IF(C25=0,"–",RANK(D25,$D$8:$D$25)) -> 18 | F25: =SUMIFS(Лист1!$H:$H,Лист1!$B:$B,$B25,Лист1!$I:$I,$C$4) -> 78139.25 | G25: =IF(F25=0,"–",RANK(F25,$F$8:$F$25)) -> 17 | H25: =COUNTIFS(Лист1!$B:$B,$B25,Лист1!$I:$I,$C$4) -> 1 | I25: =IFERROR(AVERAGEIFS(Лист1!$E:$E,Лист1!$B:$B,$B25,Лист1!$I:$I,$C$4),0) -> 6
B26: Итого по сети | C26: =SUM(C8:C25) -> 1.0556535e+09 | D26: =SUM(D8:D25) -> 1 | F26: =INDEX('1.2 Динамика'!$H$5:$H$10,MATCH($C$4,'1.2 Динамика'!$B$5:$B$10,0)) -> 1779489.2 | I26: =SUM(I8:I25) -> 613.28571

Sheet 1.2 Динамика
B2: Понедельная динамика товарооборота и товарооборота на склад (все территории)
L3: Вспомогательная таблица по дням (вся сеть)
B4: Неделя | C4: Подпись для графика | D4: Начало | E4: Конец | F4: Дней в данных | G4: Товарооборот, руб | H4: Товарооборот на склад, руб | I4: Среднедневной товарооборот, руб | L4: Дата | M4: Неделя | N4: Товарооборот, руб | O4: Складов, всего | P4: Товарооборот на склад, руб
B5: 18 | C5: =VLOOKUP(B5,Лист1!I:K,3,0) -> Неделя 1 (29.04-03.05) | D5: 43948 | E5: =D5+6 -> 43954 | F5: =COUNTIF($M$5:$M$39,B5) -> 6 | G5: =SUMIFS(Лист1!$D:$D,Лист1!$I:$I,B5) -> 836803032 | H5: =SUMIFS($P$5:$P$39,$M$5:$M$39,B5) -> 1497280.6 | I5: =IFERROR(G5/F5,0) -> 139467172 | L5: 43949 | M5: =WEEKNUM(L5,21) -> 18 | N5: =SUMIFS(Лист1!$D:$D,Лист1!$A:$A,L5) -> 1.363016e+08 | O5: =SUMIFS(Лист1!$E:$E,Лист1!$A:$A,L5) -> 545 | P5: =IFERROR(N5/O5,0) -> 250094.68
B6: 19 | C6: =VLOOKUP(B6,Лист1!I:K,3,0) -> Неделя 2 (04.05-10.05) | D6: 43955 | E6: =D6+6 -> 43961 | F6: =COUNTIF($M$5:$M$39,B6) -> 7 | G6: =SUMIFS(Лист1!$D:$D,Лист1!$I:$I,B6) -> 9.8391541e+08 | H6: =SUMIFS($P$5:$P$39,$M$5:$M$39,B6) -> 1731743 | I6: =IFERROR(G6/F6,0) -> 1.4055934e+08 | L6: 43950 | M6: =WEEKNUM(L6,21) -> 18 | N6: =SUMIFS(Лист1!$D:$D,Лист1!$A:$A,L6) -> 141455361 | O6: =SUMIFS(Лист1!$E:$E,Лист1!$A:$A,L6) -> 546 | P6: =IFERROR(N6/O6,0) -> 259075.75
B7: 20 | C7: =VLOOKUP(B7,Лист1!I:K,3,0) -> Неделя 3 (11.05-17.05) | D7: 43962 | E7: =D7+6 -> 43968 | F7: =COUNTIF($M$5:$M$39,B7) -> 7 | G7: =SUMIFS(Лист1!$D:$D,Лист1!$I:$I,B7) -> 9.4726301e+08 | H7: =SUMIFS($P$5:$P$39,$M$5:$M$39,B7) -> 1660131.2 | I7: =IFERROR(G7/F7,0) -> 1.3532329e+08 | L7: 43951 | M7: =WEEKNUM(L7,21) -> 18 | N7: =SUMIFS(Лист1!$D:$D,Лист1!$A:$A,L7) -> 1.4728811e+08 | O7: =SUMIFS(Лист1!$E:$E,Лист1!$A:$A,L7) -> 566 | P7: =IFERROR(N7/O7,0) -> 260226.35
B8: 21 | C8: =VLOOKUP(B8,Лист1!I:K,3,0) -> Неделя 4 (18.05-24.05) | D8: 43969 | E8: =D8+6 -> 43975 | F8: =COUNTIF($M$5:$M$39,B8) -> 7 | G8: =SUMIFS(Лист1!$D:$D,Лист1!$I:$I,B8) -> 1.0026919e+09 | H8: =SUMIFS($P$5:$P$39,$M$5:$M$39,B8) -> 1745761 | I8: =IFERROR(G8/F8,0) -> 1.432417e+08 | L8: 43952 | M8: =WEEKNUM(L8,21) -> 18 | N8: =SUMIFS(Лист1!$D:$D,Лист1!$A:$A,L8) -> 1.5328701e+08 | O8: =SUMIFS(Лист1!$E:$E,Лист1!$A:$A,L8) -> 565 | P8: =IFERROR(N8/O8,0) -> 271304.43
B9: 22 | C9: =VLOOKUP(B9,Лист1!I:K,3,0) -> Неделя 5 (25.05-31.05) | D9: 43976 | E9: =D9+6 -> 43982 | F9: =COUNTIF($M$5:$M$39,B9) -> 7 | G9: =SUMIFS(Лист1!$D:$D,Лист1!$I:$I,B9) -> 1.0556535e+09 | H9: =SUMIFS($P$5:$P$39,$M$5:$M$39,B9) -> 1779489.2 | I9: =IFERROR(G9/F9,0) -> 1.5080764e+08 | L9: 43953 | M9: =WEEKNUM(L9,21) -> 18 | N9: =SUMIFS(Лист1!$D:$D,Лист1!$A:$A,L9) -> 1.1569448e+08 | O9: =SUMIFS(Лист1!$E:$E,Лист1!$A:$A,L9) -> 565 | P9: =IFERROR(N9/O9,0) -> 204769
B10: 23 | C10: =VLOOKUP(B10,Лист1!I:K,3,0) -> Неделя 6 (01.06.20) | D10: 43983 | E10: =D10+6 -> 43989 | F10: =COUNTIF($M$5:$M$39,B10) -> 1 | G10: =SUMIFS(Лист1!$D:$D,Лист1!$I:$I,B10) -> 1.3603238e+08 | H10: =SUMIFS($P$5:$P$39,$M$5:$M$39,B10) -> 221190.86 | I10: =IFERROR(G10/F10,0) -> 1.3603238e+08 | L10: 43954 | M10: =WEEKNUM(L10,21) -> 18 | N10: =SUMIFS(Лист1!$D:$D,Лист1!$A:$A,L10) -> 142776468 | O10: =SUMIFS(Лист1!$E:$E,Лист1!$A:$A,L10) -> 567 | P10: =IFERROR(N10/O10,0) -> 251810.35
B11: * неполная неделя: 18-я — 6 дней (данные с 28.04), 23-я — 1 день (01.06). Неделя 23 в график не включена, чтобы не искажать динамику. | L11: 43955 | M11: =WEEKNUM(L11,21) -> 19 | N11: =SUMIFS(Лист1!$D:$D,Лист1!$A:$A,L11) -> 1.4018574e+08 | O11: =SUMIFS(Лист1!$E:$E,Лист1!$A:$A,L11) -> 567 | P11: =IFERROR(N11/O11,0) -> 247241.17
L12: 43956 | M12: =WEEKNUM(L12,21) -> 19 | N12: =SUMIFS(Лист1!$D:$D,Лист1!$A:$A,L12) -> 1.3247496e+08 | O12: =SUMIFS(Лист1!$E:$E,Лист1!$A:$A,L12) -> 567 | P12: =IFERROR(N12/O12,0) -> 233641.91
L13: 43957 | M13: =WEEKNUM(L13,21) -> 19 | N13: =SUMIFS(Лист1!$D:$D,Лист1!$A:$A,L13) -> 1.3738774e+08 | O13: =SUMIFS(Лист1!$E:$E,Лист1!$A:$A,L13) -> 567 | P13: =IFERROR(N13/O13,0) -> 242306.41
L14: 43958 | M14: =WEEKNUM(L14,21) -> 19 | N14: =SUMIFS(Лист1!$D:$D,Лист1!$A:$A,L14) -> 129568665 | O14: =SUMIFS(Лист1!$E:$E,Лист1!$A:$A,L14) -> 569 | P14: =IFERROR(N14/O14,0) -> 227712.94
L15: 43959 | M15: =WEEKNUM(L15,21) -> 19 | N15: =SUMIFS(Лист1!$D:$D,Лист1!$A:$A,L15) -> 1.6003128e+08 | O15: =SUMIFS(Лист1!$E:$E,Лист1!$A:$A,L15) -> 569 | P15: =IFERROR(N15/O15,0) -> 281250.05
L16: 43960 | M16: =WEEKNUM(L16,21) -> 19 | N16: =SUMIFS(Лист1!$D:$D,Лист1!$A:$A,L16) -> 1.3479378e+08 | O16: =SUMIFS(Лист1!$E:$E,Лист1!$A:$A,L16) -> 569 | P16: =IFERROR(N16/O16,0) -> 236895.93
L17: 43961 | M17: =WEEKNUM(L17,21) -> 19 | N17: =SUMIFS(Лист1!$D:$D,Лист1!$A:$A,L17) -> 1.4947325e+08 | O17: =SUMIFS(Лист1!$E:$E,Лист1!$A:$A,L17) -> 569 | P17: =IFERROR(N17/O17,0) -> 262694.63
L18: 43962 | M18: =WEEKNUM(L18,21) -> 20 | N18: =SUMIFS(Лист1!$D:$D,Лист1!$A:$A,L18) -> 1.203043e+08 | O18: =SUMIFS(Лист1!$E:$E,Лист1!$A:$A,L18) -> 570 | P18: =IFERROR(N18/O18,0) -> 211060.18
L19: 43963 | M19: =WEEKNUM(L19,21) -> 20 | N19: =SUMIFS(Лист1!$D:$D,Лист1!$A:$A,L19) -> 132694509 | O19: =SUMIFS(Лист1!$E:$E,Лист1!$A:$A,L19) -> 570 | P19: =IFERROR(N19/O19,0) -> 232797.38
L20: 43964 | M20: =WEEKNUM(L20,21) -> 20 | N20: =SUMIFS(Лист1!$D:$D,Лист1!$A:$A,L20) -> 1.3000029e+08 | O20: =SUMIFS(Лист1!$E:$E,Лист1!$A:$A,L20) -> 570 | P20: =IFERROR(N20/O20,0) -> 228070.68
L21: 43965 | M21: =WEEKNUM(L21,21) -> 20 | N21: =SUMIFS(Лист1!$D:$D,Лист1!$A:$A,L21) -> 1.3098483e+08 | O21: =SUMIFS(Лист1!$E:$E,Лист1!$A:$A,L21) -> 571 | P21: =IFERROR(N21/O21,0) -> 229395.51
L22: 43966 | M22: =WEEKNUM(L22,21) -> 20 | N22: =SUMIFS(Лист1!$D:$D,Лист1!$A:$A,L22) -> 1.4974858e+08 | O22: =SUMIFS(Лист1!$E:$E,Лист1!$A:$A,L22) -> 571 | P22: =IFERROR(N22/O22,0) -> 262256.71
L23: 43967 | M23: =WEEKNUM(L23,21) -> 20 | N23: =SUMIFS(Лист1!$D:$D,Лист1!$A:$A,L23) -> 1.5366991e+08 | O23: =SUMIFS(Лист1!$E:$E,Лист1!$A:$A,L23) -> 571 | P23: =IFERROR(N23/O23,0) -> 269124.19
... L39: 43983 | M39: =WEEKNUM(L39,21) -> 23 | N39: =SUMIFS(Лист1!$D:$D,Лист1!$A:$A,L39) -> 1.3603238e+08 | O39: =SUMIFS(Лист1!$E:$E,Лист1!$A:$A,L39) -> 615 | P39: =IFERROR(N39/O39,0) -> 221190.86
